<?xml version="1.0"?>
<robot xmlns:xacro="http://www.ros.org/wiki/xacro">

    <!-- The 'scale_num' and 'scale' properties are used to adjust the size of the robot's visual and collision meshes within the simulation environment. 
     This is particularly useful for visualizing the transform frames (TFs) more clearly during development and debugging. 
     The default scale is set to 1.0, which represents the actual size of the robot. It can be adjusted as necessary for better visibility. -->

    <xacro:property name="scale_num" value="1.0" />
    <xacro:property name="scale" value="${scale_num} ${scale_num} ${scale_num}" />

    <link name="base_footprint" />

    <link name="base_link">
        <visual>
            <geometry>
                <mesh filename="package://robot_description/meshes/base_link.dae" 
                    scale="${scale}"/>
            </geometry>
            <origin xyz="0.0 0.0 0.0" rpy="0.0 0.0 ${-pi/2}"/>
            <material name="black"/>
        </visual>
        <xacro:base_inertia xyz="0.0 0.0 0.0" rpy="0.0 0.0 0.0"/>
        <collision>
            <geometry>
                <mesh filename="package://robot_description/meshes/base_link.dae" 
                    scale="${scale}"/>
            </geometry>
            <origin xyz="0.0 0.0 0.0" rpy="0.0 0.0 ${-pi/2}"/>
        </collision>
    </link>

    <joint name="base_joint" type="fixed">
        <parent link="base_footprint"/>
        <child link="base_link"/>
        <origin xyz="0.0 0.0 ${scale_num * 0.028}" rpy="0.0 0.0 0.0"/>
    </joint>

    <xacro:macro name="motor_link" params="prefix">
        <link name="${prefix}_motor_link">
            <visual>
                <geometry>
                    <mesh filename="package://robot_description/meshes/motor.dae" 
                        scale="${scale}"/>
                </geometry>
                <origin xyz="0.0 0.0 0.0" rpy="0.0 0.0 0.0"/>
                <material name="silver"/>
            </visual>
            <xacro:motor_inertia xyz="0.0 0.0 0.0" rpy="0.0 0.0 0.0"/>
            <collision>
                <geometry>
                    <mesh filename="package://robot_description/meshes/motor.dae" 
                        scale="${scale}"/>
                </geometry>
                <origin xyz="0.0 0.0 0.0" rpy=" 0.0  0.0 0.0"/>
            </collision>
        </link>
    </xacro:macro>

    <xacro:motor_link prefix="left" />
    <xacro:motor_link prefix="right" />

    <joint name="base_right_motor_joint" type="fixed">
        <parent link="base_link"/>
        <child link="right_motor_link"/>
        <origin xyz=" 0.0 ${-scale_num * 0.03348} ${scale_num*0.008}" rpy="0.0 0.0 ${-pi/2}"/>
    </joint>

        <joint name="base_left_motor_joint" type="fixed">
        <parent link="base_link"/>
        <child link="left_motor_link"/>
        <origin xyz=" 0.0 ${scale_num * 0.03348} ${scale_num*0.008}" rpy=" 0.0  0.0 ${pi/2}"/>
    </joint>

    <xacro:macro name="wheel_link" params="prefix rotation">
        <link name="${prefix}_wheel_link">
            <visual>
                <geometry>
                    <mesh filename="package://robot_description/meshes/wheel.dae" 
                        scale="${scale}"/>
                </geometry>
                <origin xyz="0.0 0.0 0.0" rpy=" 0.0  0.0 ${rotation}"/>
                <material name="gray"/>
            </visual>
            <xacro:motor_inertia xyz="0.0 0.0 0.0" rpy="0.0 0.0 0.0"/>
            <collision>
                <geometry>
                    <mesh filename="package://robot_description/meshes/wheel.dae" 
                        scale="${scale}"/>
                </geometry>
                <origin xyz="0.0 0.0 0.0" rpy="0 0.0 ${rotation}"/>
            </collision>
        </link>
    </xacro:macro>


    <xacro:wheel_link prefix="right" rotation="${pi/2}"/>
    <xacro:wheel_link prefix="left" rotation="${-pi/2}"/>

    <joint name="left_motor_wheel_joint" type="continuous">
        <parent link="left_motor_link"/>
        <child link="left_wheel_link"/>
        <origin xyz="${scale_num * 0.01992} 0.0 0.0" rpy="0.0 0.0 ${pi/2}"/>
        <axis xyz=" 0.0 -1 0.0"/>
    </joint>

    <joint name="right_motor_wheel_joint" type="continuous">
        <parent link="right_motor_link"/>
        <child link="right_wheel_link"/>
        <origin xyz="${scale_num * 0.01992} 0.0 0.0" rpy="0 0 ${-pi/2}"/>
        <axis xyz="0.0 -1.0 0.0"/>
    </joint>



</robot>
